<?xml version="1.0" ?>
<mujoco model="so101_ik">
  <compiler angle="radian" autolimits="true"/>

  <default>
    <default class="so101">
      <joint damping="1" frictionloss="0.1" armature="0.005"/>
    </default>
    <default class="sts3215">
      <joint damping="0.60" frictionloss="0.052" armature="0.028"/>
    </default>
  </default>

  <worldbody>
    <body name="base" pos="0 0 0" quat="1 0 0 0" childclass="so101">
      <inertial pos="0.0137179 -5.19711e-05 0.0334843" mass="0.147" fullinertia="0.000114686 0.000136117 0.000130364 -4.59787e-07 4.97151e-06 9.75275e-08"/>
      <geom type="box" size="0.04 0.04 0.03" pos="0 0 0.015"/>
      <site group="3" name="baseframe" pos="0 0 0" quat="1 0 0 0"/>

      <body name="shoulder" pos="0.0388353 0 0.0624" quat="0 0 -1 0">
        <joint axis="0 0 1" name="shoulder_pan" type="hinge" range="-1.91986 1.91986" class="sts3215"/>
        <inertial pos="-0.0307604 -1.7e-05 -0.0252713" mass="0.100006" fullinertia="8.3759e-05 8.10403e-05 2.39783e-05 7.55525e-08 -1.16342e-06 1.54663e-07"/>
        <geom type="box" size="0.03 0.025 0.03" pos="-0.03 0 0"/>

        <body name="upper_arm" pos="-0.0303992 -0.0182778 -0.0542" quat="1 -1 -1 -1">
          <joint axis="0 0 1" name="shoulder_lift" type="hinge" range="-1.7453293 1.7453293" class="sts3215"/>
          <inertial pos="-0.089847 -0.008382 0.018409" mass="0.103" fullinertia="4.08002e-05 0.000147318 0.000142487 -1.97819e-05 -4.03016e-08 8.97326e-09"/>
          <geom type="box" size="0.06 0.015 0.02" pos="-0.06 0 0.018"/>

          <body name="lower_arm" pos="-0.11257 -0.028 0" quat="1 0 0 1">
            <joint axis="0 0 1" name="elbow_flex" type="hinge" range="-1.69 1.69" class="sts3215"/>
            <inertial pos="-0.098070 0.0032438 0.018283" mass="0.104" fullinertia="2.87438e-05 0.000159844 0.00014529 7.41152e-06 1.26409e-06 -4.90188e-08"/>
            <geom type="box" size="0.07 0.015 0.02" pos="-0.065 0 0.018"/>

            <body name="wrist" pos="-0.1349 0.0052 0" quat="1 0 0 -1">
              <joint axis="0 0 1" name="wrist_flex" type="hinge" range="-1.658063 1.658063" class="sts3215"/>
              <inertial pos="-0.000103312 -0.0386143 0.0281156" mass="0.079" fullinertia="3.68263e-05 2.5391e-05 2.1e-05 1.7893e-08 -5.28128e-08 3.6412e-06"/>
              <geom type="box" size="0.02 0.03 0.02" pos="0 -0.03 0.02"/>

              <body name="gripper" pos="5.55112e-17 -0.0611 0.0181" quat="0.0172091 -0.0172091 0.706897 0.706897">
                <joint axis="0 0 1" name="wrist_roll" type="hinge" range="-2.7438473 2.7438473" class="sts3215"/>
                <inertial pos="0.000214 0.000245 -0.025187" mass="0.087" fullinertia="2.75087e-05 4.33657e-05 3.45059e-05 -3.35241e-07 -5.7352e-06 -5.17847e-08"/>
                <geom type="box" size="0.02 0.015 0.05" pos="0 0 -0.04"/>
                <site group="3" name="gripperframe" pos="0.012 -0.000218 -0.098127" quat="1 0 1 0"/>

                <body name="moving_jaw_so101_v1" pos="0.0202 0.0188 -0.0234" quat="1 1 0 0">
                  <joint axis="0 0 1" name="gripper" type="hinge" range="-0.174533 1.7453292" class="sts3215"/>
                  <inertial pos="-0.001575 -0.0300244 0.0192755" mass="0.012" fullinertia="6.61427e-06 1.89032e-06 5.28738e-06 -3.19807e-07 -5.90717e-09 -1.09945e-07"/>
                  <geom type="box" size="0.01 0.03 0.01" pos="0 -0.03 0.02"/>
                </body>
              </body>
            </body>
          </body>
        </body>
      </body>
    </body>
  </worldbody>
</mujoco>
